Traceback (most recent call last):
  File "C:\Users\stanb\AppData\Roaming\Python\Python38\site-packages\jupyter_cache\executors\utils.py", line 51, in single_nb_execution
    executenb(
  File "C:\Users\stanb\AppData\Roaming\Python\Python38\site-packages\nbclient\client.py", line 1093, in execute
    return NotebookClient(nb=nb, resources=resources, km=km, **kwargs).execute()
  File "C:\Users\stanb\AppData\Roaming\Python\Python38\site-packages\nbclient\util.py", line 84, in wrapped
    return just_run(coro(*args, **kwargs))
  File "C:\Users\stanb\AppData\Roaming\Python\Python38\site-packages\nbclient\util.py", line 62, in just_run
    return loop.run_until_complete(coro)
  File "c:\program files\python38\lib\asyncio\base_events.py", line 616, in run_until_complete
    return future.result()
  File "C:\Users\stanb\AppData\Roaming\Python\Python38\site-packages\nbclient\client.py", line 559, in async_execute
    await self.async_execute_cell(
  File "C:\Users\stanb\AppData\Roaming\Python\Python38\site-packages\nbclient\client.py", line 854, in async_execute_cell
    self._check_raise_for_error(cell, exec_reply)
  File "C:\Users\stanb\AppData\Roaming\Python\Python38\site-packages\nbclient\client.py", line 756, in _check_raise_for_error
    raise CellExecutionError.from_cell_and_msg(cell, exec_reply_content)
nbclient.exceptions.CellExecutionError: An error occurred while executing the following cell:
------------------
from matplotlib import rcParams, cycler
import matplotlib.pyplot as plt
import numpy as np
plt.ion()
------------------

[1;31m---------------------------------------------------------------------------[0m
[1;31mModuleNotFoundError[0m                       Traceback (most recent call last)
Input [1;32mIn [1][0m, in [0;36m<module>[1;34m[0m
[1;32m----> 1[0m [38;5;28;01mfrom[39;00m [38;5;21;01mmatplotlib[39;00m [38;5;28;01mimport[39;00m rcParams, cycler
[0;32m      2[0m [38;5;28;01mimport[39;00m [38;5;21;01mmatplotlib[39;00m[38;5;21;01m.[39;00m[38;5;21;01mpyplot[39;00m [38;5;28;01mas[39;00m [38;5;21;01mplt[39;00m
[0;32m      3[0m [38;5;28;01mimport[39;00m [38;5;21;01mnumpy[39;00m [38;5;28;01mas[39;00m [38;5;21;01mnp[39;00m

[1;31mModuleNotFoundError[0m: No module named 'matplotlib'
ModuleNotFoundError: No module named 'matplotlib'

