Traceback (most recent call last):
  File "C:\Users\stanb\AppData\Roaming\Python\Python38\site-packages\jupyter_cache\executors\utils.py", line 51, in single_nb_execution
    executenb(
  File "C:\Users\stanb\AppData\Roaming\Python\Python38\site-packages\nbclient\client.py", line 1093, in execute
    return NotebookClient(nb=nb, resources=resources, km=km, **kwargs).execute()
  File "C:\Users\stanb\AppData\Roaming\Python\Python38\site-packages\nbclient\util.py", line 84, in wrapped
    return just_run(coro(*args, **kwargs))
  File "C:\Users\stanb\AppData\Roaming\Python\Python38\site-packages\nbclient\util.py", line 62, in just_run
    return loop.run_until_complete(coro)
  File "c:\program files\python38\lib\asyncio\base_events.py", line 616, in run_until_complete
    return future.result()
  File "C:\Users\stanb\AppData\Roaming\Python\Python38\site-packages\nbclient\client.py", line 559, in async_execute
    await self.async_execute_cell(
  File "C:\Users\stanb\AppData\Roaming\Python\Python38\site-packages\nbclient\client.py", line 854, in async_execute_cell
    self._check_raise_for_error(cell, exec_reply)
  File "C:\Users\stanb\AppData\Roaming\Python\Python38\site-packages\nbclient\client.py", line 756, in _check_raise_for_error
    raise CellExecutionError.from_cell_and_msg(cell, exec_reply_content)
nbclient.exceptions.CellExecutionError: An error occurred while executing the following cell:
------------------
y = np.arange(0.1, 0.28, 0.01)  # 10 cm - 28 cm incremented by 1 cm
# add your measurements here
x = np.array([])
A = np.vstack([x, np.ones(len(x))]).T
m, c = np.linalg.lstsq(A, y, rcond=None)[0]
print(m, c)
plt.plot(x, y, 'o', label='Measured data', markersize=10)
plt.plot(x, m*x + c, 'r', label='Fitted line')
plt.legend()
plt.grid('on')
plt.show()
------------------

[1;31m---------------------------------------------------------------------------[0m
[1;31mLinAlgError[0m                               Traceback (most recent call last)
Input [1;32mIn [5][0m, in [0;36m<module>[1;34m[0m
[0;32m      3[0m x [38;5;241m=[39m np[38;5;241m.[39marray([])
[0;32m      4[0m A [38;5;241m=[39m np[38;5;241m.[39mvstack([x, np[38;5;241m.[39mones([38;5;28mlen[39m(x))])[38;5;241m.[39mT
[1;32m----> 5[0m m, c [38;5;241m=[39m [43mnp[49m[38;5;241;43m.[39;49m[43mlinalg[49m[38;5;241;43m.[39;49m[43mlstsq[49m[43m([49m[43mA[49m[43m,[49m[43m [49m[43my[49m[43m,[49m[43m [49m[43mrcond[49m[38;5;241;43m=[39;49m[38;5;28;43;01mNone[39;49;00m[43m)[49m[[38;5;241m0[39m]
[0;32m      6[0m [38;5;28mprint[39m(m, c)
[0;32m      7[0m plt[38;5;241m.[39mplot(x, y, [38;5;124m'[39m[38;5;124mo[39m[38;5;124m'[39m, label[38;5;241m=[39m[38;5;124m'[39m[38;5;124mMeasured data[39m[38;5;124m'[39m, markersize[38;5;241m=[39m[38;5;241m10[39m)

File [1;32m<__array_function__ internals>:5[0m, in [0;36mlstsq[1;34m(*args, **kwargs)[0m

File [1;32mc:\program files\python38\lib\site-packages\numpy\linalg\linalg.py:2275[0m, in [0;36mlstsq[1;34m(a, b, rcond)[0m
[0;32m   2273[0m m2, n_rhs [38;5;241m=[39m b[38;5;241m.[39mshape[[38;5;241m-[39m[38;5;241m2[39m:]
[0;32m   2274[0m [38;5;28;01mif[39;00m m [38;5;241m!=[39m m2:
[1;32m-> 2275[0m     [38;5;28;01mraise[39;00m LinAlgError([38;5;124m'[39m[38;5;124mIncompatible dimensions[39m[38;5;124m'[39m)
[0;32m   2277[0m t, result_t [38;5;241m=[39m _commonType(a, b)
[0;32m   2278[0m [38;5;66;03m# FIXME: real_t is unused[39;00m

[1;31mLinAlgError[0m: Incompatible dimensions
LinAlgError: Incompatible dimensions

